<?xml version="1.0" encoding="utf-8"?>
<!-- This URDF was automatically created by SolidWorks to URDF Exporter! Originally created by Stephen Brawner (brawner@gmail.com) 
     Commit Version: 1.5.1-0-g916b5db  Build Version: 1.5.7152.31018
     For more information, please see http://wiki.ros.org/sw_urdf_exporter -->
<robot
  name="model20">
  <link
    name="base_link">
    <inertial>
      <origin
        xyz="-0.0483583892056311 -0.569818604236544 -0.0265692597772422"
        rpy="0 0 0" />
      <mass
        value="3.2125402349035" />
      <inertia
        ixx="0.00721904461730867"
        ixy="-1.93643410745551E-06"
        ixz="-3.86677335720237E-07"
        iyy="0.00580133003669007"
        iyz="3.92311651876708E-07"
        izz="0.0125108174018615" />
    </inertial>
    <visual>
      <origin
        xyz="0 0 0"
        rpy="0 0 0" />
      <geometry>
        <mesh
          filename="package://model20/meshes/base_link.STL" />
      </geometry>
      <material
        name="">
        <color
          rgba="0.752941176470588 0.752941176470588 0.752941176470588 1" />
      </material>
    </visual>
    <collision>
      <origin
        xyz="0 0 0"
        rpy="0 0 0" />
      <geometry>
        <mesh
          filename="package://model20/meshes/base_link.STL" />
      </geometry>
    </collision>
  </link>
  <link
    name="left_front_wheel_suspension">
    <inertial>
      <origin
        xyz="-0.00786753377996491 -0.0155948984609842 0.023255646876256"
        rpy="0 0 0" />
      <mass
        value="0.0651133753252895" />
      <inertia
        ixx="1.48802654908116E-05"
        ixy="1.64845451975804E-08"
        ixz="-1.56420031463122E-07"
        iyy="1.75245555055195E-05"
        iyz="-2.96403540336099E-09"
        izz="8.01010024686586E-06" />
    </inertial>
    <visual>
      <origin
        xyz="0 0 0"
        rpy="0 0 0" />
      <geometry>
        <mesh
          filename="package://model20/meshes/left_front_wheel_suspension.STL" />
      </geometry>
      <material
        name="">
        <color
          rgba="0.752941176470588 0.752941176470588 0.752941176470588 1" />
      </material>
    </visual>
    <collision>
      <origin
        xyz="0 0 0"
        rpy="0 0 0" />
      <geometry>
        <mesh
          filename="package://model20/meshes/left_front_wheel_suspension.STL" />
      </geometry>
    </collision>
  </link>
  <joint
    name="left_front_wheel_suspension_joint"
    type="prismatic">
    <origin
      xyz="-0.126408549299102 -0.497497400808498 -0.100377754287938"
      rpy="1.5707963267949 0 0" />
    <parent
      link="base_link" />
    <child
      link="left_front_wheel_suspension" />
    <axis
      xyz="0 1 0" />
    <limit
      lower="0"
      upper="0"
      effort="0"
      velocity="0" />
  </joint>
  <link
    name="left_front_wheel">
    <inertial>
      <origin
        xyz="0.0158399891826274 -4.59981459866032E-09 7.99690621500204E-08"
        rpy="0 0 0" />
      <mass
        value="0.22822169800504" />
      <inertia
        ixx="0.000789211576324214"
        ixy="-1.09995507949422E-10"
        ixz="1.91230261060059E-09"
        iyy="0.000410429434291453"
        iyz="-5.55682412519028E-16"
        izz="0.000410429434301075" />
    </inertial>
    <visual>
      <origin
        xyz="0 0 0"
        rpy="0 0 0" />
      <geometry>
        <mesh
          filename="package://model20/meshes/left_front_wheel.STL" />
      </geometry>
      <material
        name="">
        <color
          rgba="1 1 1 1" />
      </material>
    </visual>
    <collision>
      <origin
        xyz="0 0 0"
        rpy="0 0 0" />
      <geometry>
        <mesh
          filename="package://model20/meshes/left_front_wheel.STL" />
      </geometry>
    </collision>
  </link>
  <joint
    name="left_front_wheel_joint"
    type="continuous">
    <origin
      xyz="-0.01976 -0.021787 0.0099999"
      rpy="3.0841 0 3.1416" />
    <parent
      link="left_front_wheel_suspension" />
    <child
      link="left_front_wheel" />
    <axis
      xyz="1 0 0" />
    <limit
      effort="3.1"
      velocity="7" />
  </joint>
  <link
    name="right_front_wheel_suspension">
    <inertial>
      <origin
        xyz="-0.00415434378457435 -0.0156302499401892 0.023255686661272"
        rpy="0 0 0" />
      <mass
        value="0.0651133753251555" />
      <inertia
        ixx="1.48802639086072E-05"
        ixy="1.648453020563E-08"
        ixz="1.56454773175217E-07"
        iyy="1.75245555054544E-05"
        iyz="2.96411876510212E-09"
        izz="8.01010182899685E-06" />
    </inertial>
    <visual>
      <origin
        xyz="0 0 0"
        rpy="0 0 0" />
      <geometry>
        <mesh
          filename="package://model20/meshes/right_front_wheel_suspension.STL" />
      </geometry>
      <material
        name="">
        <color
          rgba="0.752941176470588 0.752941176470588 0.752941176470588 1" />
      </material>
    </visual>
    <collision>
      <origin
        xyz="0 0 0"
        rpy="0 0 0" />
      <geometry>
        <mesh
          filename="package://model20/meshes/right_front_wheel_suspension.STL" />
      </geometry>
    </collision>
  </link>
  <joint
    name="right_front_wheel_suspension_joint"
    type="prismatic">
    <origin
      xyz="0.043591 -0.4975 -0.10038"
      rpy="1.5708 0 0" />
    <parent
      link="base_link" />
    <child
      link="right_front_wheel_suspension" />
    <axis
      xyz="0 1 0" />
    <limit
      lower="0"
      upper="0"
      effort="0"
      velocity="0" />
  </joint>
  <link
    name="right_front_wheel">
    <inertial>
      <origin
        xyz="0.015839199018542 1.11022302462516E-16 0"
        rpy="0 0 0" />
      <mass
        value="0.22822169800504" />
      <inertia
        ixx="0.000789211576333899"
        ixy="-3.39635020580722E-20"
        ixz="5.20789276468475E-21"
        iyy="0.000410429434291421"
        iyz="-3.25260651745651E-19"
        izz="0.00041042943429142" />
    </inertial>
    <visual>
      <origin
        xyz="0 0 0"
        rpy="0 0 0" />
      <geometry>
        <mesh
          filename="package://model20/meshes/right_front_wheel.STL" />
      </geometry>
      <material
        name="">
        <color
          rgba="1 1 1 1" />
      </material>
    </visual>
    <collision>
      <origin
        xyz="0 0 0"
        rpy="0 0 0" />
      <geometry>
        <mesh
          filename="package://model20/meshes/right_front_wheel.STL" />
      </geometry>
    </collision>
  </link>
  <joint
    name="right_front_wheel_joint"
    type="continuous">
    <origin
      xyz="0.0077391 -0.021785 0.01"
      rpy="0.1626 0 0" />
    <parent
      link="right_front_wheel_suspension" />
    <child
      link="right_front_wheel" />
    <axis
      xyz="1 0 0" />
    <limit
      effort="3.1"
      velocity="7" />
  </joint>
  <link
    name="camera">
    <inertial>
      <origin
        xyz="-0.0113544749097687 0.00129821973144107 1.10631679103926E-05"
        rpy="0 0 0" />
      <mass
        value="0.0436119950287127" />
      <inertia
        ixx="2.35707058046401E-05"
        ixy="2.17579681215252E-08"
        ixz="1.01813691699836E-09"
        iyy="2.21058141232449E-05"
        iyz="8.85791114075603E-10"
        izz="4.29479133591155E-06" />
    </inertial>
    <visual>
      <origin
        xyz="0 0 0"
        rpy="0 0 0" />
      <geometry>
        <mesh
          filename="package://model20/meshes/camera.STL" />
      </geometry>
      <material
        name="">
        <color
          rgba="0.792156862745098 0.819607843137255 0.933333333333333 1" />
      </material>
    </visual>
    <collision>
      <origin
        xyz="0 0 0"
        rpy="0 0 0" />
      <geometry>
        <mesh
          filename="package://model20/meshes/camera.STL" />
      </geometry>
    </collision>
  </link>
  <joint
    name="camera"
    type="fixed">
    <origin
      xyz="-0.047428 -0.4557 0.02061"
      rpy="1.5708 0 1.5708" />
    <parent
      link="base_link" />
    <child
      link="camera" />
    <axis
      xyz="0 0 0" />
  </joint>
  <link
    name="camera2">
    <inertial>
      <origin
        xyz="-0.0113544534309981 0.00129834296576298 1.07114395615296E-05"
        rpy="0 0 0" />
      <mass
        value="0.0436115646020756" />
      <inertia
        ixx="2.35700541862173E-05"
        ixy="2.17644981327683E-08"
        ixz="9.97288459824813E-10"
        iyy="2.21052311066007E-05"
        iyz="6.84462776106544E-10"
        izz="4.294719281608E-06" />
    </inertial>
    <visual>
      <origin
        xyz="0 0 0"
        rpy="0 0 0" />
      <geometry>
        <mesh
          filename="package://model20/meshes/camera2.STL" />
      </geometry>
      <material
        name="">
        <color
          rgba="0.792156862745098 0.819607843137255 0.933333333333333 1" />
      </material>
    </visual>
    <collision>
      <origin
        xyz="0 0 0"
        rpy="0 0 0" />
      <geometry>
        <mesh
          filename="package://model20/meshes/camera2.STL" />
      </geometry>
    </collision>
  </link>
  <joint
    name="camera2"
    type="fixed">
    <origin
      xyz="-0.047428 -0.4697 0.089145"
      rpy="1.5708 -0.2618 1.5708" />
    <parent
      link="base_link" />
    <child
      link="camera2" />
    <axis
      xyz="0 0 0" />
  </joint>
  <link
    name="lidar">
    <inertial>
      <origin
        xyz="-0.00868778989367747 -0.00242014065569162 -0.0287648859064543"
        rpy="0 0 0" />
      <mass
        value="0.0730845706123876" />
      <inertia
        ixx="1.9580875609635E-05"
        ixy="-1.03933750344926E-07"
        ixz="4.28391241039135E-07"
        iyy="2.41250086763081E-05"
        iyz="-9.42709906914273E-09"
        izz="4.1418452244397E-05" />
    </inertial>
    <visual>
      <origin
        xyz="0 0 0"
        rpy="0 0 0" />
      <geometry>
        <mesh
          filename="package://model20/meshes/lidar.STL" />
      </geometry>
      <material
        name="">
        <color
          rgba="0.792156862745098 0.819607843137255 0.933333333333333 1" />
      </material>
    </visual>
    <collision>
      <origin
        xyz="0 0 0"
        rpy="0 0 0" />
      <geometry>
        <mesh
          filename="package://model20/meshes/lidar.STL" />
      </geometry>
    </collision>
  </link>
  <joint
    name="lidar_joint"
    type="fixed">
    <origin
      xyz="-0.039622 -0.54176 0.15412"
      rpy="0 0 1.5708" />
    <parent
      link="base_link" />
    <child
      link="lidar" />
    <axis
      xyz="0 0 0" />
  </joint>
  <link
    name="imu">
    <inertial>
      <origin
        xyz="0 0.00250000000000003 0"
        rpy="0 0 0" />
      <mass
        value="0.000510000000000001" />
      <inertia
        ixx="5.31250000000002E-09"
        ixy="5.52943107967612E-26"
        ixz="-7.37257477290141E-26"
        iyy="8.50000000000004E-09"
        iyz="1.56688295209998E-40"
        izz="5.31250000000002E-09" />
    </inertial>
    <visual>
      <origin
        xyz="0 0 0"
        rpy="0 0 0" />
      <geometry>
        <mesh
          filename="package://model20/meshes/imu.STL" />
      </geometry>
      <material
        name="">
        <color
          rgba="1 1 1 1" />
      </material>
    </visual>
    <collision>
      <origin
        xyz="0 0 0"
        rpy="0 0 0" />
      <geometry>
        <mesh
          filename="package://model20/meshes/imu.STL" />
      </geometry>
    </collision>
  </link>
  <joint
    name="imu"
    type="fixed">
    <origin
      xyz="-0.08867 -0.5725 0.10062"
      rpy="1.5708 0 0" />
    <parent
      link="base_link" />
    <child
      link="imu" />
    <axis
      xyz="0 0 0" />
  </joint>
  <link
    name="rear_wheel">
    <inertial>
      <origin
        xyz="-2.08166817117217E-17 -0.0587398646659116 -1.11022302462516E-16"
        rpy="0 0 0" />
      <mass
        value="0.350258660632925" />
      <inertia
        ixx="0.0001661084299666"
        ixy="1.57966005845945E-21"
        ixz="-9.68053563945766E-22"
        iyy="0.000114730603640893"
        iyz="3.07741679828361E-21"
        izz="0.0001661084299666" />
    </inertial>
    <visual>
      <origin
        xyz="0 0 0"
        rpy="0 0 0" />
      <geometry>
        <mesh
          filename="package://model20/meshes/rear_wheel.STL" />
      </geometry>
      <material
        name="">
        <color
          rgba="0.898039215686275 0.917647058823529 0.929411764705882 1" />
      </material>
    </visual>
    <collision>
      <origin
        xyz="0 0 0"
        rpy="0 0 0" />
      <geometry>
        <mesh
          filename="package://model20/meshes/rear_wheel.STL" />
      </geometry>
    </collision>
  </link>
  <joint
    name="rear_wheel"
    type="continuous">
    <origin
      xyz="-0.046425 -0.703 -0.10038"
      rpy="1.5708 0 0" />
    <parent
      link="base_link" />
    <child
      link="rear_wheel" />
    <axis
      xyz="0 1 0" />
  </joint>
</robot>